Traceback (most recent call last):
  File "/Users/brunosanmartin/Documents/UACh/GitHub/FuerzaDeTrabajoLosRios/.venv/lib/python3.13/site-packages/jupyter_core/utils/__init__.py", line 154, in wrapped
    asyncio.get_running_loop()
    ~~~~~~~~~~~~~~~~~~~~~~~~^^
RuntimeError: no running event loop

During handling of the above exception, another exception occurred:

Traceback (most recent call last):
  File "/Users/brunosanmartin/Documents/UACh/GitHub/FuerzaDeTrabajoLosRios/scripts/export_notebook_html.py", line 30, in export
    ep.preprocess(nb, {"metadata": {"path": str(input_path.parent)}})
    ~~~~~~~~~~~~~^^^^^^^^^^^^^^^^^^^^^^^^^^^^^^^^^^^^^^^^^^^^^^^^^^^^
  File "/Users/brunosanmartin/Documents/UACh/GitHub/FuerzaDeTrabajoLosRios/.venv/lib/python3.13/site-packages/nbconvert/preprocessors/execute.py", line 103, in preprocess
    self.preprocess_cell(cell, resources, index)
    ~~~~~~~~~~~~~~~~~~~~^^^^^^^^^^^^^^^^^^^^^^^^
  File "/Users/brunosanmartin/Documents/UACh/GitHub/FuerzaDeTrabajoLosRios/.venv/lib/python3.13/site-packages/nbconvert/preprocessors/execute.py", line 124, in preprocess_cell
    cell = self.execute_cell(cell, index, store_history=True)
  File "/Users/brunosanmartin/Documents/UACh/GitHub/FuerzaDeTrabajoLosRios/.venv/lib/python3.13/site-packages/jupyter_core/utils/__init__.py", line 158, in wrapped
    return loop.run_until_complete(inner)
           ~~~~~~~~~~~~~~~~~~~~~~~^^^^^^^
  File "/opt/homebrew/Cellar/python@3.13/3.13.3_1/Frameworks/Python.framework/Versions/3.13/lib/python3.13/asyncio/base_events.py", line 719, in run_until_complete
    return future.result()
           ~~~~~~~~~~~~~^^
  File "/Users/brunosanmartin/Documents/UACh/GitHub/FuerzaDeTrabajoLosRios/.venv/lib/python3.13/site-packages/nbclient/client.py", line 1062, in async_execute_cell
    await self._check_raise_for_error(cell, cell_index, exec_reply)
  File "/Users/brunosanmartin/Documents/UACh/GitHub/FuerzaDeTrabajoLosRios/.venv/lib/python3.13/site-packages/nbclient/client.py", line 918, in _check_raise_for_error
    raise CellExecutionError.from_cell_and_msg(cell, exec_reply_content)
nbclient.exceptions.CellExecutionError: An error occurred while executing the following cell:
------------------
# Import libraries
import pandas as pd
import numpy as np
from datetime import datetime
import warnings
import plotly.graph_objects as go
import plotly.express as px
from plotly.subplots import make_subplots

# Optional import for scipy
try:
    from scipy import stats
except ImportError:
    stats = None

# Configure pandas and warnings
pd.set_option('display.max_columns', None)
pd.set_option('display.precision', 2)
warnings.filterwarnings('ignore')
------------------


[31m---------------------------------------------------------------------------[39m
[31mModuleNotFoundError[39m                       Traceback (most recent call last)
[36mCell[39m[36m [39m[32mIn[1][39m[32m, line 2[39m
[32m      1[39m [38;5;66;03m# Import libraries[39;00m
[32m----> [39m[32m2[39m [38;5;28;01mimport[39;00m[38;5;250m [39m[34;01mpandas[39;00m[38;5;250m [39m[38;5;28;01mas[39;00m[38;5;250m [39m[34;01mpd[39;00m
[32m      3[39m [38;5;28;01mimport[39;00m[38;5;250m [39m[34;01mnumpy[39;00m[38;5;250m [39m[38;5;28;01mas[39;00m[38;5;250m [39m[34;01mnp[39;00m
[32m      4[39m [38;5;28;01mfrom[39;00m[38;5;250m [39m[34;01mdatetime[39;00m[38;5;250m [39m[38;5;28;01mimport[39;00m datetime

[31mModuleNotFoundError[39m: No module named 'pandas'

